<?xml version="1.0" ?>
<robot name="bartender_robot" xmlns:xacro="http://www.ros.org/wiki/xacro">

<xacro:include filename="$(find bartender_robot)/urdf/materials.xacro" />
<xacro:include filename="$(find bartender_robot)/urdf/bartender_robot.trans" />
<xacro:include filename="$(find bartender_robot)/urdf/bartender_robot.gazebo" />
<link name="base_link">
  <inertial>
    <origin xyz="-0.00040810804018468253 -3.552713678800501e-17 0.016706580181223032" rpy="0 0 0"/>
    <mass value="6.935188631739772"/>
    <inertia ixx="0.028142" iyy="0.028238" izz="0.054243" ixy="-0.0" iyz="-0.0" ixz="2.5e-05"/>
  </inertial>
  <visual>
    <origin xyz="0 0 0" rpy="0 0 0"/>
    <geometry>
  <mesh filename="package://bartender_robot/meshes/base_link.stl" scale="0.001 0.001 0.001"/>
    </geometry>
    <material name="silver"/>
  </visual>
  <collision>
    <origin xyz="0 0 0" rpy="0 0 0"/>
    <geometry>
      <mesh filename="package://bartender_robot/meshes/base_link.stl" scale="0.001 0.001 0.001"/>
    </geometry>
  </collision>
</link>

<link name="motor_base_1">
  <inertial>
    <origin xyz="-0.011944616237443872 -1.1102230246251566e-17 0.016403799171755752" rpy="0 0 0"/>
    <mass value="0.343534365338019"/>
    <inertia ixx="5.5e-05" iyy="9.2e-05" izz="8.2e-05" ixy="-0.0" iyz="0.0" ixz="2e-06"/>
  </inertial>
  <visual>
    <origin xyz="0.0 0.0 -0.015" rpy="0 0 0"/>
    <geometry>
  <mesh filename="package://bartender_robot/meshes/motor_base_1.stl" scale="0.001 0.001 0.001"/>
    </geometry>
    <material name="silver"/>
  </visual>
  <collision>
    <origin xyz="0.0 0.0 -0.015" rpy="0 0 0"/>
    <geometry>
      <mesh filename="package://bartender_robot/meshes/motor_base_1.stl" scale="0.001 0.001 0.001"/>
    </geometry>
  </collision>
</link>

<link name="base_upperplate_1">
  <inertial>
    <origin xyz="-1.6172448750803435e-16 -3.676205142934621e-17 0.004999999999999949" rpy="0 0 0"/>
    <mass value="1.9420933085410403"/>
    <inertia ixx="0.007942" iyy="0.007942" izz="0.015852" ixy="-0.0" iyz="0.0" ixz="0.0"/>
  </inertial>
  <visual>
    <origin xyz="0.0 0.0 -0.041" rpy="0 0 0"/>
    <geometry>
  <mesh filename="package://bartender_robot/meshes/base_upperplate_1.stl" scale="0.001 0.001 0.001"/>
    </geometry>
    <material name="silver"/>
  </visual>
  <collision>
    <origin xyz="0.0 0.0 -0.041" rpy="0 0 0"/>
    <geometry>
      <mesh filename="package://bartender_robot/meshes/base_upperplate_1.stl" scale="0.001 0.001 0.001"/>
    </geometry>
  </collision>
</link>

<link name="motor_horn_base_1">
  <inertial>
    <origin xyz="3.138091383686708e-14 5.3428299048114016e-15 0.0019561696415957355" rpy="0 0 0"/>
    <mass value="0.009818206481012393"/>
    <inertia ixx="0.0" iyy="0.0" izz="0.0" ixy="-0.0" iyz="-0.0" ixz="-0.0"/>
  </inertial>
  <visual>
    <origin xyz="0.0 0.0 -0.0475" rpy="0 0 0"/>
    <geometry>
  <mesh filename="package://bartender_robot/meshes/motor_horn_base_1.stl" scale="0.001 0.001 0.001"/>
    </geometry>
    <material name="silver"/>
  </visual>
  <collision>
    <origin xyz="0.0 0.0 -0.0475" rpy="0 0 0"/>
    <geometry>
      <mesh filename="package://bartender_robot/meshes/motor_horn_base_1.stl" scale="0.001 0.001 0.001"/>
    </geometry>
  </collision>
</link>

<link name="link1_1">
  <inertial>
    <origin xyz="0.0025732999778083376 0.0004387244111267232 0.056987216077853876" rpy="0 0 0"/>
    <mass value="18.830511805272366"/>
    <inertia ixx="0.058102" iyy="0.093565" izz="0.09509" ixy="-0.006227" iyz="-0.00017" ixz="-0.000995"/>
  </inertial>
  <visual>
    <origin xyz="0.0 0.0 -0.051" rpy="0 0 0"/>
    <geometry>
      <mesh filename="package://bartender_robot/meshes/link1_1.stl" scale="0.001 0.001 0.001"/>
    </geometry>
    <material name="silver"/>
  </visual>
  <collision>
    <origin xyz="0.0 0.0 -0.051" rpy="0 0 0"/>
    <geometry>
      <mesh filename="package://bartender_robot/meshes/link1_1.stl" scale="0.001 0.001 0.001"/>
    </geometry>
  </collision>
</link>

<link name="motor_fix_link1_1">
  <inertial>
    <origin xyz="0.00030684703129734217 0.012479258727237364 -0.028250000006648762" rpy="0 0 0"/>
    <mass value="0.0746710896046194"/>
    <inertia ixx="5.7e-05" iyy="3.7e-05" izz="2.1e-05" ixy="3e-06" iyz="-0.0" ixz="0.0"/>
  </inertial>
  <visual>
    <origin xyz="0.023374 0.016412 -0.15725" rpy="0 0 0"/>
    <geometry>
      <mesh filename="package://bartender_robot/meshes/motor_fix_link1_1.stl" scale="0.001 0.001 0.001"/>
    </geometry>
    <material name="silver"/>
  </visual>
  <collision>
    <origin xyz="0.023374 0.016412 -0.15725" rpy="0 0 0"/>
    <geometry>
      <mesh filename="package://bartender_robot/meshes/motor_fix_link1_1.stl" scale="0.001 0.001 0.001"/>
    </geometry>
  </collision>
</link>

<link name="motor_link1_1">
  <inertial>
    <origin xyz="-0.01643475104619082 0.008357164343897322 -0.019944616237441898" rpy="0 0 0"/>
    <mass value="0.343534365338019"/>
    <inertia ixx="8.2e-05" iyy="9.2e-05" izz="5.5e-05" ixy="-2e-06" iyz="0.0" ixz="2e-06"/>
  </inertial>
  <visual>
    <origin xyz="0.023584 0.01518 -0.149" rpy="0 0 0"/>
    <geometry>
      <mesh filename="package://bartender_robot/meshes/motor_link1_1.stl" scale="0.001 0.001 0.001"/>
    </geometry>
    <material name="silver"/>
  </visual>
  <collision>
    <origin xyz="0.023584 0.01518 -0.149" rpy="0 0 0"/>
    <geometry>
      <mesh filename="package://bartender_robot/meshes/motor_link1_1.stl" scale="0.001 0.001 0.001"/>
    </geometry>
  </collision>
</link>

<link name="motor_horn_link1_1">
  <inertial>
    <origin xyz="0.001928838316534058 0.00032915162363787026 -2.9781732635569824e-14" rpy="0 0 0"/>
    <mass value="0.009818206481012393"/>
    <inertia ixx="0.0" iyy="0.0" izz="0.0" ixy="0.0" iyz="-0.0" ixz="0.0"/>
  </inertial>
  <visual>
    <origin xyz="0.024152 0.004118 -0.141" rpy="0 0 0"/>
    <geometry>
      <mesh filename="package://bartender_robot/meshes/motor_horn_link1_1.stl" scale="0.001 0.001 0.001"/>
    </geometry>
    <material name="silver"/>
  </visual>
  <collision>
    <origin xyz="0.024152 0.004118 -0.141" rpy="0 0 0"/>
    <geometry>
      <mesh filename="package://bartender_robot/meshes/motor_horn_link1_1.stl" scale="0.001 0.001 0.001"/>
    </geometry>
  </collision>
</link>

<link name="link2_1">
  <inertial>
    <origin xyz="0.019445684169900824 0.0049421246241596346 -0.007216194487520228" rpy="0 0 0"/>
    <mass value="0.7710253547086547"/>
    <inertia ixx="0.000627" iyy="0.000555" izz="0.000342" ixy="1.3e-05" iyz="-2.8e-05" ixz="5e-06"/>
  </inertial>
  <visual>
    <origin xyz="0.020701 0.003529 -0.141" rpy="0 0 0"/>
    <geometry>
      <mesh filename="package://bartender_robot/meshes/link2_1.stl" scale="0.001 0.001 0.001"/>
    </geometry>
    <material name="silver"/>
  </visual>
  <collision>
    <origin xyz="0.020701 0.003529 -0.141" rpy="0 0 0"/>
    <geometry>
      <mesh filename="package://bartender_robot/meshes/link2_1.stl" scale="0.001 0.001 0.001"/>
    </geometry>
  </collision>
</link>

<link name="motor_link2_1">
  <inertial>
    <origin xyz="0.008662950578340189 0.014639969529453012 -0.021174389295863544" rpy="0 0 0"/>
    <mass value="0.343534365338019"/>
    <inertia ixx="9.2e-05" iyy="8.2e-05" izz="5.6e-05" ixy="2e-06" iyz="-4e-06" ixz="1e-06"/>
  </inertial>
  <visual>
    <origin xyz="0.015263 -0.018122 -0.147219" rpy="0 0 0"/>
    <geometry>
      <mesh filename="package://bartender_robot/meshes/motor_link2_1.stl" scale="0.001 0.001 0.001"/>
    </geometry>
    <material name="silver"/>
  </visual>
  <collision>
    <origin xyz="0.015263 -0.018122 -0.147219" rpy="0 0 0"/>
    <geometry>
      <mesh filename="package://bartender_robot/meshes/motor_link2_1.stl" scale="0.001 0.001 0.001"/>
    </geometry>
  </collision>
</link>

<link name="motor_horn_link2_1">
  <inertial>
    <origin xyz="0.00032765071508794597 -0.0019203725058804764 0.00017290455466656418" rpy="0 0 0"/>
    <mass value="0.009818206481012393"/>
    <inertia ixx="0.0" iyy="0.0" izz="0.0" ixy="-0.0" iyz="-0.0" ixz="0.0"/>
  </inertial>
  <visual>
    <origin xyz="0.004083 -0.017997 -0.139365" rpy="0 0 0"/>
    <geometry>
      <mesh filename="package://bartender_robot/meshes/motor_horn_link2_1.stl" scale="0.001 0.001 0.001"/>
    </geometry>
    <material name="silver"/>
  </visual>
  <collision>
    <origin xyz="0.004083 -0.017997 -0.139365" rpy="0 0 0"/>
    <geometry>
      <mesh filename="package://bartender_robot/meshes/motor_horn_link2_1.stl" scale="0.001 0.001 0.001"/>
    </geometry>
  </collision>
</link>

<link name="link3_1">
  <inertial>
    <origin xyz="0.013239975355927275 -0.07765762547143412 0.0069898533176015465" rpy="0 0 0"/>
    <mass value="0.5987936073400725"/>
    <inertia ixx="0.001339" iyy="0.000182" izz="0.001364" ixy="0.000203" iyz="0.000107" ixz="-1.8e-05"/>
  </inertial>
  <visual>
    <origin xyz="0.003497 -0.014561 -0.139674" rpy="0 0 0"/>
    <geometry>
      <mesh filename="package://bartender_robot/meshes/link3_1.stl" scale="0.001 0.001 0.001"/>
    </geometry>
    <material name="silver"/>
  </visual>
  <collision>
    <origin xyz="0.003497 -0.014561 -0.139674" rpy="0 0 0"/>
    <geometry>
      <mesh filename="package://bartender_robot/meshes/link3_1.stl" scale="0.001 0.001 0.001"/>
    </geometry>
  </collision>
</link>

<link name="motor_fix_link3_1">
  <inertial>
    <origin xyz="0.0004189395772044094 -0.0024550470280885195 0.00022061953423679892" rpy="0 0 0"/>
    <mass value="0.04869876038361437"/>
    <inertia ixx="5e-06" iyy="1e-05" izz="5e-06" ixy="-1e-06" iyz="-0.0" ixz="0.0"/>
  </inertial>
  <visual>
    <origin xyz="-0.023288 0.142546 -0.153815" rpy="0 0 0"/>
    <geometry>
      <mesh filename="package://bartender_robot/meshes/motor_fix_link3_1.stl" scale="0.001 0.001 0.001"/>
    </geometry>
    <material name="silver"/>
  </visual>
  <collision>
    <origin xyz="-0.023288 0.142546 -0.153815" rpy="0 0 0"/>
    <geometry>
      <mesh filename="package://bartender_robot/meshes/motor_fix_link3_1.stl" scale="0.001 0.001 0.001"/>
    </geometry>
  </collision>
</link>

<link name="motor_link3_1">
  <inertial>
    <origin xyz="0.009747847862622745 -0.013288975421585802 -0.004874357044772154" rpy="0 0 0"/>
    <mass value="0.343534365338019"/>
    <inertia ixx="7.9e-05" iyy="9.2e-05" izz="5.9e-05" ixy="-2e-06" iyz="-2e-06" ixz="9e-06"/>
  </inertial>
  <visual>
    <origin xyz="-0.015046 0.148117 -0.164112" rpy="0 0 0"/>
    <geometry>
      <mesh filename="package://bartender_robot/meshes/motor_link3_1.stl" scale="0.001 0.001 0.001"/>
    </geometry>
    <material name="silver"/>
  </visual>
  <collision>
    <origin xyz="-0.015046 0.148117 -0.164112" rpy="0 0 0"/>
    <geometry>
      <mesh filename="package://bartender_robot/meshes/motor_link3_1.stl" scale="0.001 0.001 0.001"/>
    </geometry>
  </collision>
</link>

<link name="motor_horn_link3_1">
  <inertial>
    <origin xyz="0.001846190741949083 0.0003631136075204211 0.0005343164895944552" rpy="0 0 0"/>
    <mass value="0.009818206481012393"/>
    <inertia ixx="0.0" iyy="0.0" izz="0.0" ixy="0.0" iyz="0.0" ixz="0.0"/>
  </inertial>
  <visual>
    <origin xyz="-0.036587 0.15797 -0.175077" rpy="0 0 0"/>
    <geometry>
      <mesh filename="package://bartender_robot/meshes/motor_horn_link3_1.stl" scale="0.001 0.001 0.001"/>
    </geometry>
    <material name="silver"/>
  </visual>
  <collision>
    <origin xyz="-0.036587 0.15797 -0.175077" rpy="0 0 0"/>
    <geometry>
      <mesh filename="package://bartender_robot/meshes/motor_horn_link3_1.stl" scale="0.001 0.001 0.001"/>
    </geometry>
  </collision>
</link>

<link name="link4_1">
  <inertial>
    <origin xyz="-0.0077543681654866844 -0.05206543157132765 -0.0073986661691151645" rpy="0 0 0"/>
    <mass value="1.2762304594175278"/>
    <inertia ixx="0.00437" iyy="0.001044" izz="0.004624" ixy="0.000731" iyz="-0.00017" ixz="2e-06"/>
  </inertial>
  <visual>
    <origin xyz="-0.03989 0.15732 -0.176033" rpy="0 0 0"/>
    <geometry>
      <mesh filename="package://bartender_robot/meshes/link4_1.stl" scale="0.001 0.001 0.001"/>
    </geometry>
    <material name="silver"/>
  </visual>
  <collision>
    <origin xyz="-0.03989 0.15732 -0.176033" rpy="0 0 0"/>
    <geometry>
      <mesh filename="package://bartender_robot/meshes/link4_1.stl" scale="0.001 0.001 0.001"/>
    </geometry>
  </collision>
</link>

<link name="motor_link4_1">
  <inertial>
    <origin xyz="-0.0012473361103707906 -0.014378100181126507 -0.010070029629298621" rpy="0 0 0"/>
    <mass value="0.343534365338019"/>
    <inertia ixx="8e-05" iyy="9.2e-05" izz="5.9e-05" ixy="-3e-06" iyz="3e-06" ixz="8e-06"/>
  </inertial>
  <visual>
    <origin xyz="-0.060395 0.332013 -0.17623" rpy="0 0 0"/>
    <geometry>
      <mesh filename="package://bartender_robot/meshes/motor_link4_1.stl" scale="0.001 0.001 0.001"/>
    </geometry>
    <material name="silver"/>
  </visual>
  <collision>
    <origin xyz="-0.060395 0.332013 -0.17623" rpy="0 0 0"/>
    <geometry>
      <mesh filename="package://bartender_robot/meshes/motor_link4_1.stl" scale="0.001 0.001 0.001"/>
    </geometry>
  </collision>
</link>

<link name="motor_fix_link4_1">
  <inertial>
    <origin xyz="0.0005128437509933706 -0.0024438967841333703 -0.00011117173261870894" rpy="0 0 0"/>
    <mass value="0.04869876038361437"/>
    <inertia ixx="5e-06" iyy="1e-05" izz="5e-06" ixy="-1e-06" iyz="0.0" ixz="-0.0"/>
  </inertial>
  <visual>
    <origin xyz="-0.056813 0.327062 -0.163282" rpy="0 0 0"/>
    <geometry>
      <mesh filename="package://bartender_robot/meshes/motor_fix_link4_1.stl" scale="0.001 0.001 0.001"/>
    </geometry>
    <material name="silver"/>
  </visual>
  <collision>
    <origin xyz="-0.056813 0.327062 -0.163282" rpy="0 0 0"/>
    <geometry>
      <mesh filename="package://bartender_robot/meshes/motor_fix_link4_1.stl" scale="0.001 0.001 0.001"/>
    </geometry>
  </collision>
</link>

<link name="motor_horn_link4_1">
  <inertial>
    <origin xyz="0.0018460148745002847 0.00036338533989188626 0.0005339532463921881" rpy="0 0 0"/>
    <mass value="0.009818206481012393"/>
    <inertia ixx="0.0" iyy="0.0" izz="0.0" ixy="0.0" iyz="0.0" ixz="0.0"/>
  </inertial>
  <visual>
    <origin xyz="-0.071249 0.344576 -0.182036" rpy="0 0 0"/>
    <geometry>
      <mesh filename="package://bartender_robot/meshes/motor_horn_link4_1.stl" scale="0.001 0.001 0.001"/>
    </geometry>
    <material name="silver"/>
  </visual>
  <collision>
    <origin xyz="-0.071249 0.344576 -0.182036" rpy="0 0 0"/>
    <geometry>
      <mesh filename="package://bartender_robot/meshes/motor_horn_link4_1.stl" scale="0.001 0.001 0.001"/>
    </geometry>
  </collision>
</link>

<joint name="Rigid 1" type="fixed">
  <origin xyz="0.0 0.0 0.015" rpy="0 0 0"/>
  <parent link="base_link"/>
  <child link="motor_base_1"/>
</joint>

<joint name="Rigid 2" type="fixed">
  <origin xyz="0.0 0.0 0.041" rpy="0 0 0"/>
  <parent link="base_link"/>
  <child link="base_upperplate_1"/>
</joint>

<joint name="Revolute 3" type="continuous">
  <origin xyz="0.0 0.0 0.0325" rpy="0 0 0"/>
  <parent link="motor_base_1"/>
  <child link="motor_horn_base_1"/>
  <axis xyz="0.0 0.0 1.0"/>
</joint>

<joint name="Rigid 4" type="fixed">
  <origin xyz="0.0 0.0 0.0035" rpy="0 0 0"/>
  <parent link="motor_horn_base_1"/>
  <child link="link1_1"/>
</joint>

<joint name="Rigid 5" type="fixed">
  <origin xyz="-0.023374 -0.016412 0.10625" rpy="0 0 0"/>
  <parent link="link1_1"/>
  <child link="motor_fix_link1_1"/>
</joint>

<joint name="Rigid 6" type="fixed">
  <origin xyz="-0.00021 0.001232 -0.00825" rpy="0 0 0"/>
  <parent link="motor_fix_link1_1"/>
  <child link="motor_link1_1"/>
</joint>

<joint name="Revolute 7" type="continuous">
  <origin xyz="-0.000568 0.011062 -0.008" rpy="0 0 0"/>
  <parent link="motor_link1_1"/>
  <child link="motor_horn_link1_1"/>
  <axis xyz="0.985776 0.168066 0.0"/>
</joint>

<joint name="Rigid 8" type="fixed">
  <origin xyz="0.003451 0.000589 0.0" rpy="0 0 0"/>
  <parent link="motor_horn_link1_1"/>
  <child link="link2_1"/>
</joint>

<joint name="Rigid 9" type="fixed">
  <origin xyz="0.005438 0.021651 0.006219" rpy="0 0 0"/>
  <parent link="link2_1"/>
  <child link="motor_link2_1"/>
</joint>

<joint name="Revolute 10" type="continuous">
  <origin xyz="0.01118 -0.000125 -0.007854" rpy="0 0 0"/>
  <parent link="motor_link2_1"/>
  <child link="motor_horn_link2_1"/>
  <axis xyz="0.167408 -0.981919 0.088377"/>
</joint>

<joint name="Rigid 12" type="fixed">
  <origin xyz="0.000586 -0.003436 0.000309" rpy="0 0 0"/>
  <parent link="motor_horn_link2_1"/>
  <child link="link3_1"/>
</joint>

<joint name="Rigid 13" type="fixed">
  <origin xyz="0.026785 -0.157107 0.014141" rpy="0 0 0"/>
  <parent link="link3_1"/>
  <child link="motor_fix_link3_1"/>
</joint>

<joint name="Rigid 14" type="fixed">
  <origin xyz="-0.008242 -0.005571 0.010297" rpy="0 0 0"/>
  <parent link="motor_fix_link3_1"/>
  <child link="motor_link3_1"/>
</joint>

<joint name="Revolute 15" type="continuous">
  <origin xyz="0.021541 -0.009853 0.010965" rpy="0 0 0"/>
  <parent link="motor_link3_1"/>
  <child link="motor_horn_link3_1"/>
  <axis xyz="0.943896 0.185516 0.27321"/>
</joint>

<joint name="Rigid 16" type="fixed">
  <origin xyz="0.003303 0.00065 0.000956" rpy="0 0 0"/>
  <parent link="motor_horn_link3_1"/>
  <child link="link4_1"/>
</joint>

<joint name="Rigid 18" type="fixed">
  <origin xyz="0.003582 -0.004951 0.012948" rpy="0 0 0"/>
  <parent link="motor_fix_link4_1"/>
  <child link="motor_link4_1"/>
</joint>

<joint name="Rigid 19" type="fixed">
  <origin xyz="0.016923 -0.169742 -0.012751" rpy="0 0 0"/>
  <parent link="link4_1"/>
  <child link="motor_fix_link4_1"/>
</joint>

<joint name="Revolute 20" type="continuous">
  <origin xyz="0.010854 -0.012563 0.005806" rpy="0 0 0"/>
  <parent link="motor_link4_1"/>
  <child link="motor_horn_link4_1"/>
  <axis xyz="0.943896 0.185516 0.27321"/>
</joint>

</robot>
